<?xml version="1.0"?>
<robot xmlns:xacro="http://www.ros.org/wiki/xacro">
    <xacro:macro name="zoidstein_head">
        <link name="base_link" />
        <link name="neck_yaw_link" />
        <link name="neck_pitch_link" />
        <link name="gaze" />

        <joint name="base_joint" type="fixed">
            <parent link="base_link"/>
            <child link="neck_yaw_link"/>
            <origin xyz="0 0 0" rpy="0 0 0" />
        </joint>

        <joint name="neck_yaw_joint" type="revolute">
            <parent link="base_link"/>
            <child link="neck_yaw_link"/>
            <origin xyz="0 0 0.0545" rpy="0 0 0"/>
            <axis xyz="0 0 1"/>
            <limit velocity="1.0" effort="1" lower="-0.8726" upper="0.8726" />
        </joint>

        <joint name="neck_pitch_joint" type="revolute">
            <parent link="neck_yaw_link"/>
            <child link="neck_pitch_link"/>
            <origin xyz="0 0 0.02867" rpy="0 0 0"/>
            <axis xyz="0 1 0"/>
            <limit velocity="1.0" effort="1" lower="-0.8726" upper="0.8726" />
        </joint>

        <joint name="gaze_joint" type="fixed">
            <parent link="neck_pitch_link"/>
            <child link="gaze"/>
            <origin xyz="0.0556 0 0.06578" rpy="0 0 0"/>
        </joint>
    </xacro:macro>
</robot>